<?xml version="1.0" encoding="UTF-8"?>
<!-- https://mujoco.readthedocs.io/en/latest/overview.html?highlight=hello.xml#examples -->
<mujoco>
   <option gravity="0 0 0" />
   <worldbody>
      <light diffuse=".5 .5 .5" pos="0 0 10" dir="0 0 -1" />
      <geom type="plane" size="3.5 3.5 0.1" rgba="1 1 1 1" />
      <body pos="0.5 0 0.1" euler="0 90 0">
         <geom type="cylinder" size="0.05 0.5" rgba="1 0 0 1" />
         <joint type="hinge" axis="-1 0 0" pos="0 0 -0.5" />
         <body pos="0 0 1" euler="0 0 0">
            <geom type="cylinder" size="0.05 0.5" rgba="0 1 0 1" />
            <joint type="hinge" axis="-1 0 0" pos="0 0 -0.5" />
            <body pos="0 0 1" euler="0 0 0">
               <geom type="cylinder" size="0.05 0.5" rgba="0 0 1 1" />
               <joint type="hinge" axis="-1 0 0" pos="0 0 -0.5" />
               <site name="tip" size="0.1" pos="0 0 0.5" />
            </body>
         </body>
      </body>
   </worldbody>
   <sensor>
      <framepos objtype="site" objname="tip" />
   </sensor>
</mujoco>